Workbook

Sheet Калькулятор
B1: Калькулятор потужності та ціни СЕС (перший дзвінок)
B3: Введення даних (заповнює менеджер)
B4: Місячне споживання, кВт·год | C4: 9000
B5: Тип станції | C5: Мережева | G5: =IF(C5="Мережева","мережева","гібридна")
B6: Розташування | C6: Дах | G6: =IF(C6="Дах","дах","земля")
B7: Форма оплати | C7: Готівка | G7: =IF(C7="Готівка","готівка","ПДВ")
B8: Години автономії (тільки для гібридної)
B10: Розрахунок потужності
B11: Добове споживання, кВт·год | C11: =C4/30
B12: Денне споживання 80%, кВт·год | C12: =C11*0.8
B13: Нічне споживання 20%, кВт·год | C13: =C11*0.2
B14: Денні години (8:00–20:00) | C14: =12
B15: Цільова потужність (середнє денне), кВт | C15: =C12/C14
B17: Підбір обладнання
B18: Підібраний інвертор DEYE, кВт | C18: =IF(C5="Мережева",IF(SUMPRODUCT(MAX((Дані!$A$2:$A$18<=C15*1.1)*Дані!$A$2:$A$18))=0,MIN(Дані!$A$2:$A$18),SUMPRODUCT(MAX((Дані!$A$2:$A$18<=C15*1.1)*Дані!$A$2:$A$18))),IF(SUMPRODUCT(MAX((Дані!$C$2:$C$18<=C15*1.1)*Дані!$C$2:$C$18))=0,MIN(Дані!$C$2:$C$18),SUMPRODUCT(MAX((Дані!$C$2:$C$18<=C15*1.1)*Дані!$C$2:$C$18))))
B19: Примітка | C19: =IF(C5="Мережева",IF(C15*1.1<MIN(Дані!$A$2:$A$18),"Менше мін. — взято мінімальну станцію",""),IF(C15*1.1<MIN(Дані!$C$2:$C$18),"Менше мін. — взято мінімальну станцію",""))
B20: Панелі (потужність і кількість) | C20: ="500 Вт/шт × "&C42&" шт = "&TEXT(C42*0.5,"0.0")&" кВт"
B21: Орієнтовна ціна
B22: Потужність станції для ціни, кВт | C22: =C18 | G22: =IF(C22<=75,50,100)
B23: Ціна за кВт, $ | C23: =IFERROR(VLOOKUP(G5&"|"&G6&"|"&G7&"|"&G22,Дані!$L$2:$M$8,2,0),"уточнити у менеджера")
B24: Курс, грн/$ | C24: 44.3
B25: Орієнтовна ціна, $ | C25: =IF(ISNUMBER(C23),C22*C23,"уточнити у менеджера")
B26: Орієнтовна ціна, грн | C26: =IF(ISNUMBER(C25),C25*C24,"уточнити у менеджера")
B28: Автономія та комплект АКБ (тільки для гібридної станції)
B29: Потрібна ємність АКБ, кВт·год | C29: =IF(C5="Гібридна",C8*C11/24,"—")
B30: Система АКБ (авто: LV / HV) | C30: =IF(C5="Гібридна",IF(N(C29)>50,"HV","LV"),"—")
B31: Підібрана модель АКБ | C31: =IF(C5="Гібридна",IF(C30="LV",'Акумулятори LV'!$B$3,'Акумулятори HV'!$Q$3),"—")
B32: Ємність одного модуля, кВт·год | C32: =IF(C30="LV",'Акумулятори LV'!$B$4,'Акумулятори HV'!$Q$4)
B33: Кількість модулів АКБ | C33: =IF(C5="Гібридна",IF(C8>0,CEILING(C29/C32,1),0),"—")
B34: Підсумкова ємність АКБ, кВт·год | C34: =IF(C5="Гібридна",IF(C8>0,C33*C32,0),"—")
B35: BMS (модель) | C35: =IF(C5="Гібридна",IF(C30="LV","вбудований",'Акумулятори HV'!$Q$7),"—")
B36: Стійка (модель) | C36: =IF(C5="Гібридна",IF(C30="LV","—",'Акумулятори HV'!$Q$10),"—")
B37: Кількість стійок / BMS, шт | C37: =IF(C5="Гібридна",IF(C8>0,IF(C30="LV",0,CEILING(C33/'Акумулятори HV'!$Q$11,1)),0),"—")
B38: Ціна комплекту АКБ з ПДВ, $ | C38: =IF(C5="Гібридна",IF(C8>0,C33*IF(C30="LV",'Акумулятори LV'!$B$5,'Акумулятори HV'!$Q$5)+C37*IF(C30="LV",0,'Акумулятори HV'!$Q$8)+C37*IF(C30="LV",0,'Акумулятори HV'!$Q$12),0),"—")
B39: Ціна комплекту АКБ без ПДВ, $ | C39: =IF(C5="Гібридна",IF(C8>0,C33*IF(C30="LV",'Акумулятори LV'!$B$6,'Акумулятори HV'!$Q$6)+C37*IF(C30="LV",0,'Акумулятори HV'!$Q$9)+C37*IF(C30="LV",0,'Акумулятори HV'!$Q$13),0),"—")
B41: Кріплення (монтаж панелей)
B42: Кількість панелей (≈, 500 Вт/шт) | C42: =CEILING(C22/0.5,1)
B43: Тип даху | C43: Профнастил
B44: Ціна кріплення за панель, $ | C44: =VLOOKUP(C43,Дані!$O$2:$P$6,2,0)
B45: Вартість кріплень, $ | C45: =IF(C6="Дах",C42*C44,"уточнити у менеджера (наземна)")
...

Sheet Дані
A1: Інвертор DEYE мережевий, кВт | C1: Інвертор DEYE гібридний, кВт | H1: Вид | I1: Розташування | J1: Оплата | K1: Потужність, кВт | L1: Ключ | M1: Ціна, $/кВт | O1: Тип даху | P1: Ціна кріплення за панель, $
A2: 10 | C2: 5 | H2: мережева | I2: дах | J2: готівка | K2: 50 | L2: =H2&"|"&I2&"|"&J2&"|"&K2 | M2: 340 | O2: Профнастил | P2: 12
A3: 15 | C3: 6 | H3: мережева | I3: дах | J3: ПДВ | K3: 50 | L3: =H3&"|"&I3&"|"&J3&"|"&K3 | M3: 400 | O3: Плаский дах | P3: 38
A4: 18 | C4: 8 | H4: гібридна | I4: дах | J4: готівка | K4: 50 | L4: =H4&"|"&I4&"|"&J4&"|"&K4 | M4: 600 | O4: Вітровий спойлер (багатоповерхівка) | P4: 40
A5: 20 | C5: 10 | H5: мережева | I5: дах | J5: готівка | K5: 100 | L5: =H5&"|"&I5&"|"&J5&"|"&K5 | M5: 310 | O5: Керамічна черепиця | P5: 42
A6: 25 | C6: 12 | H6: мережева | I6: дах | J6: ПДВ | K6: 100 | L6: =H6&"|"&I6&"|"&J6&"|"&K6 | M6: 360 | O6: Скатний дах | P6: 20
A7: 30 | C7: 14 | H7: мережева | I7: земля | J7: готівка | K7: 100 | L7: =H7&"|"&I7&"|"&J7&"|"&K7 | M7: 432
A8: 35 | C8: 15 | H8: гібридна | I8: дах | J8: готівка | K8: 100 | L8: =H8&"|"&I8&"|"&J8&"|"&K8 | M8: 557
A9: 45 | C9: 16
A10: 50 | C10: 18
A11: 60 | C11: 20
A12: 80 | C12: 25
A13: 100 | C13: 30
A14: 110 | C14: 40
A15: 120 | C15: 50
A16: 125 | C16: 60
A17: 130 | C17: 75
A18: 135 | C18: 80

Sheet Інструкція
A1: Як користуватися калькулятором:
A2: 1. Заповніть жовті клітинки на аркуші «Калькулятор» (перелік нижче).
A3: 2. Для гібридної станції вкажіть кількість годин автономії.
A4: 3. Решта рахується автоматично: потужність, інвертор, ціна, АКБ та кріплення.
A6: Які клітинки заповнює менеджер вручну (жовті):
A7: • C4 — Місячне споживання, кВт·год
A8: • C5 — Тип станції: Мережева / Гібридна
A9: • C6 — Розташування: Дах / Земля
A10: • C7 — Форма оплати: Готівка / ПДВ
A11: • C8 — Години автономії (тільки для гібридної станції)
A12: • C24 — Курс, грн/$ (оновлювати за потреби)
A13: • C43 — Тип даху (вибір зі списку)
... A38: Таблиці інверторів, цін і типів даху редагуються на аркуші «Дані».

Sheet Акумулятори LV
A1: Акумулятори LV (низьковольтні, 48–51.2 В) — BMS вбудований у модуль
A3: Авто-модель LV (найкраще заповнення) → | B3: =IF(N('Калькулятор'!$C$29)>0,INDEX($A$9:$A$21,MATCH(MIN($I$9:$I$21),$I$9:$I$21,0)),INDEX($A$9:$A$21,MATCH(MAX($C$9:$C$21),$C$9:$C$21,0)))
A4: Ємність модуля, кВт·год | B4: =VLOOKUP($B$3,$A$9:$F$21,3,0)
A5: Ціна модуля з ПДВ, $ | B5: =VLOOKUP($B$3,$A$9:$F$21,5,0)
A6: Ціна модуля без ПДВ, $ | B6: =VLOOKUP($B$3,$A$9:$F$21,6,0)
A8: Модель | B8: Опис | C8: Ємність, кВт·год | D8: Напруга, В | E8: Ціна з ПДВ, $ | F8: Ціна без ПДВ, $ | H8: Модулів (авто) | I8: Зайва ємність (оцінка)
A9: SE-F16-С | B9: DEYE SE-F16-С LiFePO4 LV 51.2V 314Ah | C9: 16 | D9: 51.2 | E9: 2080 | F9: 1800 | H9: =IF(N('Калькулятор'!$C$29)>0,CEILING('Калькулятор'!$C$29/C9,1),0) | I9: =IF(N('Калькулятор'!$C$29)>0,H9*C9-'Калькулятор'!$C$29+H9*0.0001,"")
A10: RW-F16 | B10: DEYE RW-F16 LiFePO4 LV 51.2V 314Ah | C10: 14.4 | D10: 51.2 | E10: 2275 | F10: 1935 | H10: =IF(N('Калькулятор'!$C$29)>0,CEILING('Калькулятор'!$C$29/C10,1),0) | I10: =IF(N('Калькулятор'!$C$29)>0,H10*C10-'Калькулятор'!$C$29+H10*0.0001,"")
A11: SE-F12-C | B11: DEYE SE-F12-C LiFePO4 LV 51.2V 230Ah | C11: 11.8 | D11: 51.2 | E11: 1650 | F11: 1470 | H11: =IF(N('Калькулятор'!$C$29)>0,CEILING('Калькулятор'!$C$29/C11,1),0) | I11: =IF(N('Калькулятор'!$C$29)>0,H11*C11-'Калькулятор'!$C$29+H11*0.0001,"")
A12: SE-F5 Pro-C | B12: DEYE SE-F5 Pro LiFePO4 LV 51.2V 100Ah | C12: 5.12 | D12: 51.2 | E12: 850 | F12: 720 | H12: =IF(N('Калькулятор'!$C$29)>0,CEILING('Калькулятор'!$C$29/C12,1),0) | I12: =IF(N('Калькулятор'!$C$29)>0,H12*C12-'Калькулятор'!$C$29+H12*0.0001,"")
A13: SE-G5.1 Pro-B | B13: DEYE SE-G5.1 Pro-B LiFePO4 LV 51.2V 100Ah | C13: 5.12 | D13: 51.2 | E13: 880 | F13: 750 | H13: =IF(N('Калькулятор'!$C$29)>0,CEILING('Калькулятор'!$C$29/C13,1),0) | I13: =IF(N('Калькулятор'!$C$29)>0,H13*C13-'Калькулятор'!$C$29+H13*0.0001,"")
A14: DL5.0C-H | B14: Dyness DL5.0C Heat LiFePO4 51.2V 100Ah | C14: 5.12 | D14: 51.2 | E14: 810 | F14: 720 | H14: =IF(N('Калькулятор'!$C$29)>0,CEILING('Калькулятор'!$C$29/C14,1),0) | I14: =IF(N('Калькулятор'!$C$29)>0,H14*C14-'Калькулятор'!$C$29+H14*0.0001,"")
A15: DL5.0C Pro | B15: Dyness DL5.0C Pro LiFePO4 51.2V 100Ah | C15: 5.12 | D15: 51.2 | E15: 870 | F15: 770 | H15: =IF(N('Калькулятор'!$C$29)>0,CEILING('Калькулятор'!$C$29/C15,1),0) | I15: =IF(N('Калькулятор'!$C$29)>0,H15*C15-'Калькулятор'!$C$29+H15*0.0001,"")
A16: Powerbrick | B16: Dyness Powerbrick LiFePO4 51.2V 280Ah | C16: 14.4 | D16: 51.2 | E16: 2130 | F16: 1950 | H16: =IF(N('Калькулятор'!$C$29)>0,CEILING('Калькулятор'!$C$29/C16,1),0) | I16: =IF(N('Калькулятор'!$C$29)>0,H16*C16-'Калькулятор'!$C$29+H16*0.0001,"")
A17: RS-R51100A | B17: Ecosolex RS-R51100A LV 51.2V 100Ah | C17: 5.12 | D17: 51.2 | E17: 780 | F17: 660 | H17: =IF(N('Калькулятор'!$C$29)>0,CEILING('Калькулятор'!$C$29/C17,1),0) | I17: =IF(N('Калькулятор'!$C$29)>0,H17*C17-'Калькулятор'!$C$29+H17*0.0001,"")
A18: GSL051200AB | B18: GSL LV 51.2V 200Ah | C18: 10.24 | D18: 51.2 | E18: 1650 | F18: 1450 | H18: =IF(N('Калькулятор'!$C$29)>0,CEILING('Калькулятор'!$C$29/C18,1),0) | I18: =IF(N('Калькулятор'!$C$29)>0,H18*C18-'Калькулятор'!$C$29+H18*0.0001,"")
A19: GSL051100AB | B19: GSL LV 51.2V 100Ah | C19: 5.12 | D19: 51.2 | E19: 830 | F19: 710 | H19: =IF(N('Калькулятор'!$C$29)>0,CEILING('Калькулятор'!$C$29/C19,1),0) | I19: =IF(N('Калькулятор'!$C$29)>0,H19*C19-'Калькулятор'!$C$29+H19*0.0001,"")
A20: GSL51100-3.5U | B20: GSL51100 LV 51.2V 100Ah | C20: 5.12 | D20: 51.2 | E20: 775 | F20: 675 | H20: =IF(N('Калькулятор'!$C$29)>0,CEILING('Калькулятор'!$C$29/C20,1),0) | I20: =IF(N('Калькулятор'!$C$29)>0,H20*C20-'Калькулятор'!$C$29+H20*0.0001,"")
A21: ZN-P48100ESA1 | B21: GSL LV 48V 100Ah | C21: 4.8 | D21: 48 | E21: 750 | F21: 650 | H21: =IF(N('Калькулятор'!$C$29)>0,CEILING('Калькулятор'!$C$29/C21,1),0) | I21: =IF(N('Калькулятор'!$C$29)>0,H21*C21-'Калькулятор'!$C$29+H21*0.0001,"")

Sheet Акумулятори HV
A1: Акумулятори HV (високовольтні) — окремий BMS + стійка
O2: Підбір для калькулятора
O3: Авто-модель HV (найкраще заповнення) → | Q3: =IF(N('Калькулятор'!$C$29)>0,INDEX($A$9:$A$13,MATCH(MIN($U$9:$U$13),$U$9:$U$13,0)),INDEX($A$9:$A$13,MATCH(MAX($C$9:$C$13),$C$9:$C$13,0)))
O4: Ємність модуля, кВт·год | Q4: =VLOOKUP($Q$3,$A$9:$M$13,3,0)
O5: Ціна модуля з ПДВ, $ | Q5: =VLOOKUP($Q$3,$A$9:$M$13,4,0)
O6: Ціна модуля без ПДВ, $ | Q6: =VLOOKUP($Q$3,$A$9:$M$13,5,0)
O7: BMS (модель) | Q7: =VLOOKUP($Q$3,$A$9:$M$13,6,0)
A8: Модель батареї | B8: Опис | C8: Ємність, кВт·год | D8: Ціна бат. з ПДВ, $ | E8: Ціна бат. без ПДВ, $ | F8: BMS модель | G8: BMS з ПДВ, $ | H8: BMS без ПДВ, $ | I8: Стійка модель | J8: Батарей на стійку | K8: Стійка з ПДВ, $ | L8: Стійка без ПДВ, $ | O8: Ціна BMS з ПДВ, $ | Q8: =VLOOKUP($Q$3,$A$9:$M$13,7,0) | S8: Модулів | T8: Стійок | U8: Зайва ємність (оцінка)
A9: BOS-B-Pack16-A3 | B9: DEYE BOS-B PRO LiFePO4 HV 51.2V 314Ah | C9: 16.08 | D9: 2040 | E9: 1750 | F9: BOS-B-PDU-2-А | G9: 1580 | H9: 1450 | I9: RACK/BOS-B-PRO | J9: 15 | K9: 770 | L9: 680 | O9: Ціна BMS без ПДВ, $ | Q9: =VLOOKUP($Q$3,$A$9:$M$13,8,0) | S9: =IF(N('Калькулятор'!$C$29)>0,CEILING('Калькулятор'!$C$29/C9,1),0) | T9: =IF(S9>0,CEILING(S9/J9,1),0) | U9: =IF(N('Калькулятор'!$C$29)>0,S9*C9-'Калькулятор'!$C$29+S9*0.0001,"")
A10: BOS-G | B10: DEYE BOS-G LiFePO4 HV 51.2V 100Ah (no BMS) | C10: 5.12 | D10: 870 | E10: 755 | F10: BOS-G-PDU-2 | G10: 870 | H10: 755 | I10: 3U-LRACK | J10: 8 | K10: 330 | L10: 290 | O10: Стійка (модель) | Q10: =VLOOKUP($Q$3,$A$9:$M$13,9,0) | S10: =IF(N('Калькулятор'!$C$29)>0,CEILING('Калькулятор'!$C$29/C10,1),0) | T10: =IF(S10>0,CEILING(S10/J10,1),0) | U10: =IF(N('Калькулятор'!$C$29)>0,S10*C10-'Калькулятор'!$C$29+S10*0.0001,"")
A11: BOS-A | B11: DEYE BOS-A LiFePO4 HV 38.4V 200Ah | C11: 7.68 | D11: 1290 | E11: 1110 | F11: BOS-A-PDU-2 1000V/160A | G11: 1120 | H11: 960 | I11: BOS-A-Rack11 | J11: 11 | K11: 370 | L11: 330 | O11: Батарей на стійку, шт | Q11: =VLOOKUP($Q$3,$A$9:$M$13,10,0) | S11: =IF(N('Калькулятор'!$C$29)>0,CEILING('Калькулятор'!$C$29/C11,1),0) | T11: =IF(S11>0,CEILING(S11/J11,1),0) | U11: =IF(N('Калькулятор'!$C$29)>0,S11*C11-'Калькулятор'!$C$29+S11*0.0001,"")
A12: GSL-51314HV | B12: GSL HV 51.2V 314Ah | C12: 16 | D12: 1840 | E12: 1660 | F12: BMS GSL51314 120-1000V 200A | G12: 1350 | H12: 1215 | I12: Стійка GSL 8 батарей | J12: 8 | K12: 480 | L12: 435 | O12: Ціна стійки з ПДВ, $ | Q12: =VLOOKUP($Q$3,$A$9:$M$13,11,0) | S12: =IF(N('Калькулятор'!$C$29)>0,CEILING('Калькулятор'!$C$29/C12,1),0) | T12: =IF(S12>0,CEILING(S12/J12,1),0) | U12: =IF(N('Калькулятор'!$C$29)>0,S12*C12-'Калькулятор'!$C$29+S12*0.0001,"")
A13: S51100 | B13: Dyness STACK HV 51.2V 100Ah | C13: 5.12 | D13: 860 | E13: 760 | F13: SBDU100 | G13: 800 | H13: 710 | I13: QB32U8BAT | J13: 8 | K13: 215 | L13: 205 | O13: Ціна стійки без ПДВ, $ | Q13: =VLOOKUP($Q$3,$A$9:$M$13,12,0) | S13: =IF(N('Калькулятор'!$C$29)>0,CEILING('Калькулятор'!$C$29/C13,1),0) | T13: =IF(S13>0,CEILING(S13/J13,1),0) | U13: =IF(N('Калькулятор'!$C$29)>0,S13*C13-'Калькулятор'!$C$29+S13*0.0001,"")
